Workbook

Sheet Sheet1
A1: old GPIO | B1: GPIO | C1: Phases
A2: 46 | B2: 36 | C2: 1.8786192 | D2: 1.9244194 | E2: 1.9664232 | F2: 0.0045957565 | G2: 0.03890705 | H2: 0.06932926 | I2: 0.09583473 | J2: 0.11840153 | K2: 0.13701248 | L2: 0.15164852 | M2: 0.16229916 | N2: 0.1689539 | O2: 0.17160891 | P2: 0.17026043 | Q2: 0.16490935 | R2: 0.1555605 | S2: 0.1422224 | T2: 0.12490654 | U2: 0.10362816 | V2: 0.07840443 | W2: 0.04925728 | X2: 0.01621151 | Y2: 1.9792948 | Z2: 1.9385366 | AA2: 1.8939704 | AB2: 1.8456335
A3: 23 | B3: 3 | C3: 1.8818245 | D3: 1.9276344 | E3: 1.9696474 | F3: 0.007829666 | G3: 0.04214859 | H3: 0.07257748 | I3: 0.09908962 | J3: 0.12166214 | K3: 0.14027691 | L3: 0.15491676 | M3: 0.16557024 | N3: 0.17222595 | O3: 0.17488098 | P3: 0.17353249 | Q3: 0.16818047 | R3: 0.15882969 | S3: 0.14548874 | T3: 0.12816906 | U3: 0.10688496 | V3: 0.08165551 | W3: 0.05250168 | X3: 0.019447327 | Y3: 1.982522 | Z3: 1.9417542 | AA3: 1.8971786 | AB3: 1.8488312
A4: 47 | B4: 41 | C4: 1.8796835 | D4: 1.9016733 | E4: 1.9197634 | F4: 1.933942 | G4: 1.9441938 | H4: 1.9505129 | I4: 1.9528933 | J4: 1.951332 | K4: 1.9458313 | L4: 1.9363967 | M4: 1.9230338 | N4: 1.905754 | O4: 1.8845739 | P4: 1.8595096 | Q4: 1.8305817 | R4: 1.7978144 | S4: 1.7612344 | T4: 1.720869 | U4: 1.6767521 | V4: 1.6289167 | W4: 1.577403 | X4: 1.5222464 | Y4: 1.4634905 | Z4: 1.4011793 | AA4: 1.3353548 | AB4: 1.2660694
A5: 22 | B5: 4 | C5: 1.8828888 | D5: 1.9048824 | E5: 1.9229784 | F5: 1.9371586 | G5: 1.9474134 | H5: 1.9537344 | I5: 1.9561148 | J5: 1.9545536 | K5: 1.9490519 | L5: 1.9396143 | M5: 1.9262486 | N5: 1.9089661 | O5: 1.8877813 | P5: 1.86271 | Q5: 1.8337765 | R5: 1.8010015 | S5: 1.7644119 | T5: 1.724038 | U5: 1.6799115 | V5: 1.6320658 | W5: 1.5805407 | X5: 1.5253724 | Y5: 1.4666042 | Z5: 1.4042788 | AA5: 1.3384418 | AB5: 1.2691402
A6: 55 | B6: 40 | C6: 1.8818121 | D6: 1.8562897 | E6: 1.8269073 | F6: 1.7936859 | G6: 1.7566566 | H6: 1.7158461 | I6: 1.6712875 | J6: 1.6230164 | K6: 1.5710689 | L6: 1.5154848 | M6: 1.4563065 | N6: 1.3935766 | O6: 1.3273411 | P6: 1.2576475 | Q6: 1.1845455 | R6: 1.1080837 | S6: 1.0283136 | T6: 0.94528955 | U6: 0.85906214 | V6: 0.7696886 | W6: 0.67722225 | X6: 0.58172035 | Y6: 0.48323727 | Z6: 0.38183117 | AA6: 0.27755642 | AB6: 0.17047119
A7: 7 | B7: 5 | C7: 1.8850174 | D7: 1.8594896 | E7: 1.8301 | F7: 1.7968721 | G7: 1.7598343 | H7: 1.7190142 | I7: 1.6744462 | J7: 1.6261634 | K7: 1.5742054 | L7: 1.518609 | M7: 1.4594183 | N7: 1.3966743 | O7: 1.3304251 | P7: 1.2607183 | Q7: 1.1876001 | R7: 1.1111221 | S7: 1.0313358 | T7: 0.9482936 | U7: 0.86205095 | V7: 0.77266026 | W7: 0.6801767 | X7: 0.5846548 | Y7: 0.48615456 | Z7: 0.38472843 | AA7: 0.2804346 | AB7: 0.1733303
A8: 63 | B8: 39 | C8: 1.8828764 | D8: 1.8336526 | E8: 1.7807055 | F8: 1.7240763 | G8: 1.663808 | H8: 1.599946 | I8: 1.5325403 | J8: 1.4616393 | K8: 1.387291 | L8: 1.3095512 | M8: 1.2284727 | N8: 1.1441078 | O8: 1.0565147 | P8: 0.96574974 | Q8: 0.8718691 | R8: 0.77493 | S8: 0.67499256 | T8: 0.57211304 | U8: 0.46635056 | V8: 0.3577633 | W8: 0.24641132 | X8: 0.13234901 | Y8: 0.015637398 | Z8: 1.8963356 | AA8: 1.7744962 | AB8: 1.6501808
A9: 15 | B9: 0 | C9: 1.8860817 | D9: 1.8368473 | E9: 1.7838879 | F9: 1.7272463 | G9: 1.6669645 | H9: 1.6030893 | I9: 1.5356693 | J9: 1.4647503 | K9: 1.3903875 | L9: 1.3126316 | M9: 1.231535 | N9: 1.1471548 | O9: 1.0595427 | P9: 0.96875954 | Q9: 0.87486076 | R9: 0.77790356 | S9: 0.67794514 | T9: 0.57504654 | U9: 0.46926403 | V9: 0.36065578 | W9: 0.24928284 | X9: 0.1352005 | Y9: 0.018468857 | Z9: 1.8991451 | AA9: 1.7772847 | AB9: 1.6529464
A10: 70 | B10: 38 | C10: 1.8818121 | D10: 1.8562897 | E10: 1.8269073 | F10: 1.7936859 | G10: 1.7566566 | H10: 1.7158461 | I10: 1.6712875 | J10: 1.6230164 | K10: 1.5710689 | L10: 1.5154848 | M10: 1.4563065 | N10: 1.3935766 | O10: 1.3273411 | P10: 1.2576475 | Q10: 1.1845455 | R10: 1.1080837 | S10: 1.0283136 | T10: 0.94528955 | U10: 0.85906214 | V10: 0.7696886 | W10: 0.67722225 | X10: 0.58172035 | Y10: 0.48323727 | Z10: 0.38183117 | AA10: 0.27755642 | AB10: 0.17047119
A11: 31 | B11: 1 | C11: 1.8850174 | D11: 1.8594896 | E11: 1.8301 | F11: 1.7968721 | G11: 1.7598343 | H11: 1.7190142 | I11: 1.6744462 | J11: 1.6261644 | K11: 1.5742054 | L11: 1.518609 | M11: 1.4594183 | N11: 1.3966743 | O11: 1.3304251 | P11: 1.2607183 | Q11: 1.1876001 | R11: 1.1111221 | S11: 1.0313377 | T11: 0.9482936 | U11: 0.86205095 | V11: 0.77266026 | W11: 0.6801767 | X11: 0.5846548 | Y11: 0.48615456 | Z11: 0.38472843 | AA11: 0.2804346 | AB11: 0.1733303
A12: 71 | B12: 37 | C12: 1.8796844 | D12: 1.9016733 | E12: 1.9197634 | F12: 1.933942 | G12: 1.9441948 | H12: 1.950514 | I12: 1.9528933 | J12: 1.951332 | K12: 1.9458323 | L12: 1.9363967 | M12: 1.9230338 | N12: 1.905755 | O12: 1.8845739 | P12: 1.8595104 | Q12: 1.8305826 | R12: 1.7978153 | S12: 1.7612352 | T12: 1.720869 | U12: 1.6767521 | V12: 1.6289177 | W12: 1.577403 | X12: 1.5222472 | Y12: 1.4634914 | Z12: 1.4011793 | AA12: 1.3353559 | AB12: 1.2660694
A13: 30 | B13: 2 | C13: 1.8828888 | D13: 1.9048834 | E13: 1.9229784 | F13: 1.9371595 | G13: 1.9474144 | H13: 1.9537354 | I13: 1.9561157 | J13: 1.9545536 | K13: 1.9490528 | L13: 1.9396143 | M13: 1.9262486 | N13: 1.9089661 | O13: 1.8877813 | P13: 1.862711 | Q13: 1.8337774 | R13: 1.8010015 | S13: 1.7644119 | T13: 1.7240391 | U13: 1.6799126 | V13: 1.6320667 | W13: 1.5805415 | X13: 1.5253735 | Y13: 1.4666042 | Z13: 1.4042788 | AA13: 1.3384428 | AB13: 1.2691402
... A73: 32 | B73: 26 | C73: 1.8780174 | D73: 0.0034351347 | E73: 0.12599373 | F73: 0.24562073 | G73: 0.36223602 | H73: 0.47576427 | I73: 0.5861244 | J73: 0.6932392 | K73: 0.7970295 | L73: 0.8974161 | M73: 0.99432087 | N73: 1.0876637 | O73: 1.1773682 | P73: 1.2633572 | Q73: 1.3455553 | R73: 1.4238873 | S73: 1.4982815 | T73: 1.5686665 | U73: 1.6349734 | V73: 1.6971378 | W73: 1.7550955 | X73: 1.8087873 | Y73: 1.8581551 | Z73: 1.9031467 | AA73: 1.9437151 | AB73: 1.9798117

Sheet move right smaller grad
A1: old GPIO | B1: GPIO | C1: Phases | K1: -
A2: 46 | B2: 36 | C2: 1.8786192 | D2: 1.8781289 | E2: 1.8766594 | F2: 1.8742095 | G2: 1.87078 | H2: 1.8663731 | I2: 1.8609875 | J2: 1.8546267 | K2: 1.84729 | L2: 1.8389796 | M2: 1.8296976 | N2: 1.8194456 | O2: 1.8082247 | P2: 1.7960396 | Q2: 1.7828912
A3: 23 | B3: 3 | C3: 1.8818245 | D3: 1.8813334 | E3: 1.8798639 | F3: 1.8774128 | G3: 1.8739843 | H3: 1.8695745 | I3: 1.8641882 | J3: 1.8578262 | K3: 1.8504878 | L3: 1.8421755 | M3: 1.8328916 | N3: 1.8226365 | O3: 1.8114138 | P3: 1.7992258 | Q3: 1.7860736
A4: 47 | B4: 41 | C4: 1.8796835 | D4: 1.8997812 | E4: 1.9189262 | F4: 1.9371119 | G4: 1.9543352 | H4: 1.9705935 | I4: 1.9858837 | J4: 0.000201 | K4: 0.013544082 | L4: 0.02590847 | M4: 0.03729248 | N4: 0.047694203 | O4: 0.05711174 | P4: 0.06554222 | Q4: 0.072981834
A5: 22 | B5: 4 | C5: 1.8828888 | D5: 1.9029913 | E5: 1.9221392 | F5: 1.9403296 | G5: 1.9575567 | H5: 1.9738188 | I5: 1.9891129 | J5: 0.003434181 | K5: 0.016778946 | L5: 0.029147148 | M5: 0.040534016 | N5: 0.050937653 | O5: 0.060357094 | P5: 0.06878948 | Q5: 0.07623196
A6: 55 | B6: 40 | C6: 1.8818121 | D6: 1.9019127 | E6: 1.9210607 | F6: 1.9392481 | G6: 1.9564753 | H6: 1.9727354 | I6: 1.9880276 | J6: 0.002347946 | K6: 0.01569271 | L6: 0.028059008 | M6: 0.039445877 | N6: 0.049848557 | O6: 0.059267998 | P6: 0.06769848 | Q6: 0.07514095
A7: 7 | B7: 5 | C7: 1.8850174 | D7: 1.9051228 | E7: 1.9242744 | F7: 1.9424667 | G7: 1.9596978 | H7: 1.9759626 | I7: 1.9912577 | J7: 0.005580903 | K7: 0.018928528 | L7: 0.031297684 | M7: 0.042687416 | N7: 0.053092957 | O7: 0.06251335 | P7: 0.07094669 | Q7: 0.07839012
A8: 63 | B8: 39 | C8: 1.8828764 | D8: 1.8823863 | E8: 1.8809156 | F8: 1.8784647 | G8: 1.8750353 | H8: 1.8706255 | I8: 1.8652391 | J8: 1.8588772 | K8: 1.8515377 | L8: 1.8432255 | M8: 1.8339405 | N8: 1.8236847 | O8: 1.8124619 | P8: 1.8002719 | Q8: 1.7871199
A9: 15 | B9: 0 | C9: 1.8860817 | D9: 1.8855915 | E9: 1.884121 | F9: 1.88167 | G9: 1.8782396 | H9: 1.8738298 | I9: 1.8684416 | J9: 1.8620768 | K9: 1.8547363 | L9: 1.8464222 | M9: 1.8371353 | N9: 1.8268765 | O9: 1.8156509 | P9: 1.8034592 | Q9: 1.7903032
A10: 70 | B10: 38 | C10: 1.8818121 | D10: 1.8607607 | E10: 1.8387632 | F10: 1.8158226 | G10: 1.7919475 | H10: 1.7671374 | I10: 1.7414016 | J10: 1.7147427 | K10: 1.6871653 | L10: 1.6586771 | M10: 1.629281 | N10: 1.5989857 | O10: 1.5677929 | P10: 1.5357122 | Q10: 1.5027466
A11: 31 | B11: 1 | C11: 1.8850174 | D11: 1.8639611 | E11: 1.841959 | F11: 1.8190136 | G11: 1.7951326 | H11: 1.7703171 | I11: 1.7445755 | J11: 1.7179098 | K11: 1.6903275 | L11: 1.6618328 | M11: 1.6324311 | N11: 1.602128 | O11: 1.5709295 | P11: 1.5388412 | Q11: 1.505868
A12: 71 | B12: 37 | C12: 1.8796844 | D12: 1.858635 | E12: 1.8366404 | F12: 1.8137053 | G12: 1.789832 | H12: 1.765027 | I12: 1.7392942 | J12: 1.712639 | K12: 1.6850662 | L12: 1.6565819 | M12: 1.6271905 | N12: 1.5968992 | O12: 1.5657111 | P12: 1.5336342 | Q12: 1.5006741
A13: 30 | B13: 2 | C13: 1.8828888 | D13: 1.8618355 | E13: 1.8398371 | F13: 1.8168945 | G13: 1.7930174 | H13: 1.7682056 | I13: 1.7424669 | J13: 1.715806 | K13: 1.6882277 | L13: 1.6597366 | M13: 1.6303395 | N13: 1.6000414 | O13: 1.5688467 | P13: 1.5367632 | Q13: 1.5037956
... A73: 32 | B73: 26 | C73: 1.8780174 | D73: 1.8544998 | E73: 1.8300438 | F73: 1.8046551 | G73: 1.7783383 | H73: 1.7510996 | I73: 1.7229424 | J73: 1.6938745 | K73: 1.6638986 | L73: 1.6330223 | M73: 1.6012506 | N73: 1.5685911 | O73: 1.5350475 | P73: 1.5006266 | Q73: 1.4653349

Sheet scaled
A1: old gpio | B1: GPIO
A2: 46 | B2: 41 | C2: =Sheet1!C2*32 -> 60.115814 | D2: =Sheet1!D2*32 -> 61.581421 | E2: =Sheet1!E2*32 -> 62.925542 | F2: =Sheet1!F2*32 -> 0.14706421 | G2: =Sheet1!G2*32 -> 1.2450256 | H2: =Sheet1!H2*32 -> 2.2185363 | I2: =Sheet1!I2*32 -> 3.0667114 | J2: =Sheet1!J2*32 -> 3.788849 | ... AB2: =Sheet1!AB2*32 -> 59.060272
A3: 23 | B3: 4 | C3: =Sheet1!C3*32 -> 60.218384 | D3: =Sheet1!D3*32 -> 61.684301 | E3: =Sheet1!E3*32 -> 63.028717 | F3: =Sheet1!F3*32 -> 0.25054931 | G3: =Sheet1!G3*32 -> 1.3487549 | H3: =Sheet1!H3*32 -> 2.3224794 | I3: =Sheet1!I3*32 -> 3.1708678 | J3: =Sheet1!J3*32 -> 3.8931885 | ... AB3: =Sheet1!AB3*32 -> 59.162598
A4: 47 | B4: 40 | C4: =Sheet1!C4*32 -> 60.149872 | D4: =Sheet1!D4*32 -> 60.853546 | E4: =Sheet1!E4*32 -> 61.432429 | F4: =Sheet1!F4*32 -> 61.886144 | G4: =Sheet1!G4*32 -> 62.214202 | H4: =Sheet1!H4*32 -> 62.416413 | I4: =Sheet1!I4*32 -> 62.492586 | J4: =Sheet1!J4*32 -> 62.442624 | ... AB4: =Sheet1!AB4*32 -> 40.514221
A5: 22 | B5: 5 | C5: =Sheet1!C5*32 -> 60.252442 | D5: =Sheet1!D5*32 -> 60.956237 | E5: =Sheet1!E5*32 -> 61.535309 | F5: =Sheet1!F5*32 -> 61.989075 | G5: =Sheet1!G5*32 -> 62.317229 | H5: =Sheet1!H5*32 -> 62.519501 | I5: =Sheet1!I5*32 -> 62.595674 | J5: =Sheet1!J5*32 -> 62.545715 | ... AB5: =Sheet1!AB5*32 -> 40.612486
A6: 55 | B6: 39 | C6: =Sheet1!C6*32 -> 60.217987 | D6: =Sheet1!D6*32 -> 59.40127 | E6: =Sheet1!E6*32 -> 58.461034 | F6: =Sheet1!F6*32 -> 57.397949 | G6: =Sheet1!G6*32 -> 56.213011 | H6: =Sheet1!H6*32 -> 54.907075 | I6: =Sheet1!I6*32 -> 53.4812 | J6: =Sheet1!J6*32 -> 51.936525 | ... AB6: =Sheet1!AB6*32 -> 5.4550781
A7: 7 | B7: 0 | C7: =Sheet1!C7*32 -> 60.320557 | D7: =Sheet1!D7*32 -> 59.503667 | E7: =Sheet1!E7*32 -> 58.5632 | F7: =Sheet1!F7*32 -> 57.499907 | G7: =Sheet1!G7*32 -> 56.314698 | H7: =Sheet1!H7*32 -> 55.008454 | I7: =Sheet1!I7*32 -> 53.582278 | J7: =Sheet1!J7*32 -> 52.037229 | ... AB7: =Sheet1!AB7*32 -> 5.5465696
A8: 63 | B8: 38 | C8: =Sheet1!C8*32 -> 60.252045 | D8: =Sheet1!D8*32 -> 58.676883 | E8: =Sheet1!E8*32 -> 56.982576 | F8: =Sheet1!F8*32 -> 55.170442 | G8: =Sheet1!G8*32 -> 53.241856 | H8: =Sheet1!H8*32 -> 51.198272 | I8: =Sheet1!I8*32 -> 49.04129 | J8: =Sheet1!J8*32 -> 46.772458 | ... AB8: =Sheet1!AB8*32 -> 52.805786
A9: 15 | B9: 1 | C9: =Sheet1!C9*32 -> 60.354614 | D9: =Sheet1!D9*32 -> 58.779114 | E9: =Sheet1!E9*32 -> 57.084413 | F9: =Sheet1!F9*32 -> 55.271882 | G9: =Sheet1!G9*32 -> 53.342864 | H9: =Sheet1!H9*32 -> 51.298858 | I9: =Sheet1!I9*32 -> 49.141418 | J9: =Sheet1!J9*32 -> 46.87201 | ... AB9: =Sheet1!AB9*32 -> 52.894285
A10: 70 | B10: 37 | C10: =Sheet1!C10*32 -> 60.217987 | D10: =Sheet1!D10*32 -> 59.40127 | E10: =Sheet1!E10*32 -> 58.461034 | F10: =Sheet1!F10*32 -> 57.397949 | G10: =Sheet1!G10*32 -> 56.213011 | H10: =Sheet1!H10*32 -> 54.907075 | I10: =Sheet1!I10*32 -> 53.4812 | J10: =Sheet1!J10*32 -> 51.936525 | ... AB10: =Sheet1!AB10*32 -> 5.4550781
A11: 31 | B11: 2 | C11: =Sheet1!C11*32 -> 60.320557 | D11: =Sheet1!D11*32 -> 59.503667 | E11: =Sheet1!E11*32 -> 58.5632 | F11: =Sheet1!F11*32 -> 57.499907 | G11: =Sheet1!G11*32 -> 56.314698 | H11: =Sheet1!H11*32 -> 55.008454 | I11: =Sheet1!I11*32 -> 53.582278 | J11: =Sheet1!J11*32 -> 52.037261 | ... AB11: =Sheet1!AB11*32 -> 5.5465696
A12: 71 | B12: 36 | C12: =Sheet1!C12*32 -> 60.149901 | D12: =Sheet1!D12*32 -> 60.853546 | E12: =Sheet1!E12*32 -> 61.432429 | F12: =Sheet1!F12*32 -> 61.886144 | G12: =Sheet1!G12*32 -> 62.214234 | H12: =Sheet1!H12*32 -> 62.416448 | I12: =Sheet1!I12*32 -> 62.492586 | J12: =Sheet1!J12*32 -> 62.442624 | ... AB12: =Sheet1!AB12*32 -> 40.514221
A13: 30 | B13: 3 | C13: =Sheet1!C13*32 -> 60.252442 | D13: =Sheet1!D13*32 -> 60.956269 | E13: =Sheet1!E13*32 -> 61.535309 | F13: =Sheet1!F13*32 -> 61.989104 | G13: =Sheet1!G13*32 -> 62.317261 | H13: =Sheet1!H13*32 -> 62.519533 | I13: =Sheet1!I13*32 -> 62.595702 | J13: =Sheet1!J13*32 -> 62.545715 | ... AB13: =Sheet1!AB13*32 -> 40.612486
... A73: 32 | B73: 28 | C73: =Sheet1!C73*32 -> 60.096557 | D73: =Sheet1!D73*32 -> 0.10992431 | E73: =Sheet1!E73*32 -> 4.0317994 | F73: =Sheet1!F73*32 -> 7.8598634 | G73: =Sheet1!G73*32 -> 11.591553 | H73: =Sheet1!H73*32 -> 15.224457 | I73: =Sheet1!I73*32 -> 18.755981 | J73: =Sheet1!J73*32 -> 22.183654 | ... AB73: =Sheet1!AB73*32 -> 63.353974

Sheet move across
A1: GPIO
A2: 36 | B2: 1.8786163 | C2: 1.8785068 | D2: 1.8782396 | E2: 1.8778172 | F2: 1.8772364 | G2: 1.876499 | H2: 1.8756056 | I2: 1.8745556 | J2: 1.8733474 | K2: 1.8719845 | L2: 1.8704634 | M2: 1.8687868 | N2: 1.8669529 | O2: 1.8649635 | P2: 1.8628178 | Q2: 1.8605146
A3: 3 | B3: 1.8818207 | C3: 1.881712 | D3: 1.881444 | E3: 1.8810215 | F3: 1.8804407 | G3: 1.8797045 | H3: 1.8788099 | I3: 1.8777591 | J3: 1.8765516 | K3: 1.8751879 | L3: 1.8736666 | M3: 1.8719903 | N3: 1.8701553 | O3: 1.868165 | P3: 1.8660194 | Q3: 1.8637161
A4: 41 | B4: 1.8813257 | C4: 1.8894501 | D4: 1.8974199 | E4: 1.9052382 | F4: 1.9129039 | G4: 1.9204159 | H4: 1.9277744 | I4: 1.9349794 | J4: 1.9420319 | K4: 1.9489288 | L4: 1.9556713 | M4: 1.9622604 | N4: 1.9686929 | O4: 1.9749727 | P4: 1.9810963 | Q4: 1.9870644
A5: 4 | B5: 1.8845309 | C5: 1.8926572 | D5: 1.900629 | E5: 1.9084492 | F5: 1.9161168 | G5: 1.9236307 | H5: 1.9309902 | I5: 1.9381971 | J5: 1.9452506 | K5: 1.9521494 | L5: 1.9588938 | M5: 1.9654837 | N5: 1.9719192 | O5: 1.978199 | P5: 1.9843245 | Q5: 1.9902935
A6: 40 | B6: 1.8834553 | C6: 1.8915795 | D6: 1.8995514 | E6: 1.9073715 | F6: 1.9150372 | G6: 1.9225502 | H6: 1.9299108 | I6: 1.9371166 | J6: 1.9441689 | K6: 1.9510679 | L6: 1.9578112 | M6: 1.9644012 | N6: 1.9708357 | O6: 1.9771156 | P6: 1.9832401 | Q6: 1.9892092
A7: 5 | B7: 1.8866615 | C7: 1.8947878 | D7: 1.9027606 | E7: 1.9105825 | F7: 1.9182501 | G7: 1.9257652 | H7: 1.9331263 | I7: 1.9403353 | J7: 1.9473888 | K7: 1.9542885 | L7: 1.9610338 | M7: 1.9676256 | N7: 1.974062 | O7: 1.9803429 | P7: 1.9864683 | Q7: 1.9924393
A8: 39 | B8: 1.8828726 | C8: 1.8827628 | D8: 1.8824967 | E8: 1.8820734 | F8: 1.8814937 | G8: 1.8807564 | H8: 1.8798618 | I8: 1.8788109 | J8: 1.8776034 | K8: 1.8762388 | L8: 1.8747187 | M8: 1.8730421 | N8: 1.8712072 | O8: 1.8692169 | P8: 1.8670702 | Q8: 1.8647671
A9: 0 | B9: 1.8860798 | C9: 1.8859701 | D9: 1.8857021 | E9: 1.8852786 | F9: 1.8846979 | G9: 1.8839616 | H9: 1.883066 | I9: 1.8820151 | J9: 1.8808079 | K9: 1.8794441 | L9: 1.877922 | M9: 1.8762445 | N9: 1.8744097 | O9: 1.8724194 | P9: 1.8702717 | Q9: 1.8679686
A10: 38 | B10: 1.8801622 | C10: 1.8718262 | D10: 1.8633366 | E10: 1.8546963 | F10: 1.8459053 | G10: 1.8369626 | H10: 1.8278694 | I10: 1.8186264 | J10: 1.8092327 | K10: 1.7996892 | L10: 1.7899961 | M10: 1.7801552 | N10: 1.7701645 | O10: 1.7600249 | P10: 1.7497377 | Q10: 1.7393026
A11: 1 | B11: 1.8833685 | C11: 1.8750286 | D11: 1.866538 | E11: 1.8578959 | F11: 1.8491029 | G11: 1.8401575 | H11: 1.8310623 | I11: 1.8218164 | J11: 1.8124208 | K11: 1.8028756 | L11: 1.7931814 | M11: 1.7833376 | N11: 1.7733439 | O11: 1.7632036 | P11: 1.7529135 | Q11: 1.7424755
A12: 37 | B12: 1.8780345 | C12: 1.8696985 | D12: 1.8612108 | E12: 1.8525715 | F12: 1.8437815 | G12: 1.8348408 | H12: 1.8257483 | I12: 1.8165064 | J12: 1.8071146 | K12: 1.7975721 | L12: 1.7878819 | M12: 1.7780417 | N12: 1.7680521 | O12: 1.7579145 | P12: 1.7476292 | Q12: 1.737195
A13: 2 | B13: 1.8812389 | C13: 1.872901 | D13: 1.8644123 | E13: 1.855771 | F13: 1.8469791 | G13: 1.8380356 | H13: 1.8289423 | I13: 1.8196974 | J13: 1.8103037 | K13: 1.8007593 | L13: 1.7910662 | M13: 1.7812241 | N13: 1.7712325 | O13: 1.7610922 | P13: 1.750804 | Q13: 1.7403678
... A73: 26 | B73: 1.8761711 | C73: 1.8668461 | D73: 1.8573713 | E73: 1.8477468 | F73: 1.8379717 | G73: 1.8280468 | H73: 1.8179741 | I73: 1.8077507 | J73: 1.7973796 | K73: 1.7868605 | L73: 1.7761937 | M73: 1.765379 | N73: 1.7544174 | O73: 1.7433082 | P73: 1.7320518 | Q73: 1.7206508

Sheet across and back
A1: GPIO
A2: 36 | B2: 1.8786192 | C2: 1.8781289 | D2: 1.8766594 | E2: 1.8742095 | F2: 1.87078 | G2: 1.8663731 | H2: 1.8609875 | I2: 1.8546267 | J2: 1.8609875 | K2: 1.8663731 | L2: 1.87078 | M2: 1.8742095 | N2: 1.8766594 | O2: 1.8781289 | P2: 1.8786192
A3: 3 | B3: 1.8818245 | C3: 1.8813334 | D3: 1.8798639 | E3: 1.8774128 | F3: 1.8739843 | G3: 1.8695745 | H3: 1.8641882 | I3: 1.8578262 | J3: 1.8641882 | K3: 1.8695745 | L3: 1.8739843 | M3: 1.8774128 | N3: 1.8798639 | O3: 1.8813334 | P3: 1.8818245
A4: 41 | B4: 1.8796835 | C4: 1.8997812 | D4: 1.9189262 | E4: 1.9371119 | F4: 1.9543352 | G4: 1.9705935 | H4: 1.9858837 | I4: 0.000201 | J4: 1.9858837 | K4: 1.9705935 | L4: 1.9543352 | M4: 1.9371119 | N4: 1.9189262 | O4: 1.8997812 | P4: 1.8796835
A5: 4 | B5: 1.8828888 | C5: 1.9029913 | D5: 1.9221392 | E5: 1.9403296 | F5: 1.9575567 | G5: 1.9738188 | H5: 1.9891129 | I5: 0.003434181 | J5: 1.9891129 | K5: 1.9738188 | L5: 1.9575567 | M5: 1.9403296 | N5: 1.9221392 | O5: 1.9029913 | P5: 1.8828888
A6: 40 | B6: 1.8818121 | C6: 1.9019127 | D6: 1.9210607 | E6: 1.9392481 | F6: 1.9564753 | G6: 1.9727354 | H6: 1.9880276 | I6: 0.002347946 | J6: 1.9880276 | K6: 1.9727354 | L6: 1.9564753 | M6: 1.9392481 | N6: 1.9210607 | O6: 1.9019127 | P6: 1.8818121
A7: 5 | B7: 1.8850174 | C7: 1.9051228 | D7: 1.9242744 | E7: 1.9424667 | F7: 1.9596978 | G7: 1.9759626 | H7: 1.9912577 | I7: 0.005580903 | J7: 1.9912577 | K7: 1.9759626 | L7: 1.9596978 | M7: 1.9424667 | N7: 1.9242744 | O7: 1.9051228 | P7: 1.8850174
A8: 39 | B8: 1.8828764 | C8: 1.8823863 | D8: 1.8809156 | E8: 1.8784647 | F8: 1.8750353 | G8: 1.8706255 | H8: 1.8652391 | I8: 1.8588772 | J8: 1.8652391 | K8: 1.8706255 | L8: 1.8750353 | M8: 1.8784647 | N8: 1.8809156 | O8: 1.8823863 | P8: 1.8828764
A9: 0 | B9: 1.8860817 | C9: 1.8855915 | D9: 1.884121 | E9: 1.88167 | F9: 1.8782396 | G9: 1.8738298 | H9: 1.8684416 | I9: 1.8620768 | J9: 1.8684416 | K9: 1.8738298 | L9: 1.8782396 | M9: 1.88167 | N9: 1.884121 | O9: 1.8855915 | P9: 1.8860817
A10: 38 | B10: 1.8818121 | C10: 1.8607607 | D10: 1.8387632 | E10: 1.8158226 | F10: 1.7919475 | G10: 1.7671374 | H10: 1.7414016 | I10: 1.7147427 | J10: 1.7414016 | K10: 1.7671374 | L10: 1.7919475 | M10: 1.8158226 | N10: 1.8387632 | O10: 1.8607607 | P10: 1.8818121
A11: 1 | B11: 1.8850174 | C11: 1.8639611 | D11: 1.841959 | E11: 1.8190136 | F11: 1.7951326 | G11: 1.7703171 | H11: 1.7445755 | I11: 1.7179098 | J11: 1.7445755 | K11: 1.7703171 | L11: 1.7951326 | M11: 1.8190136 | N11: 1.841959 | O11: 1.8639611 | P11: 1.8850174
A12: 37 | B12: 1.8796844 | C12: 1.858635 | D12: 1.8366404 | E12: 1.8137053 | F12: 1.789832 | G12: 1.765027 | H12: 1.7392942 | I12: 1.712639 | J12: 1.7392942 | K12: 1.765027 | L12: 1.789832 | M12: 1.8137053 | N12: 1.8366404 | O12: 1.858635 | P12: 1.8796844
A13: 2 | B13: 1.8828888 | C13: 1.8618355 | D13: 1.8398371 | E13: 1.8168945 | F13: 1.7930174 | G13: 1.7682056 | H13: 1.7424669 | I13: 1.715806 | J13: 1.7424669 | K13: 1.7682056 | L13: 1.7930174 | M13: 1.8168945 | N13: 1.8398371 | O13: 1.8618355 | P13: 1.8828888
... A73: 26 | B73: 1.8780174 | C73: 1.8544998 | D73: 1.8300438 | E73: 1.8046551 | F73: 1.7783383 | G73: 1.7510996 | H73: 1.7229424 | I73: 1.6938745 | J73: 1.7229424 | K73: 1.7510996 | L73: 1.7783383 | M73: 1.8046551 | N73: 1.8300438 | O73: 1.8544998 | P73: 1.8780174

Sheet aab
A1: GPIO
A2: 36 | B2: 1.8786192 | C2: 1.8781289 | D2: 1.8766594 | E2: 1.8742095 | F2: 1.8712435 | G2: 1.8678894 | H2: 1.8649635 | I2: 1.8616858 | J2: 1.6314669 | K2: 1.401086 | L2: 1.1705513
A3: 3 | B3: 1.8818245 | C3: 1.8813334 | D3: 1.8798639 | E3: 1.8774128 | F3: 1.8744469 | G3: 1.8710918 | H3: 1.868165 | I3: 1.8648871 | J3: 0.09493351 | K3: 0.32480145 | L3: 0.5544815
A4: 41 | B4: 1.8796835 | C4: 1.8997812 | D4: 1.9189262 | E4: 1.9371119 | F4: 1.9523193 | G4: 1.9654961 | H4: 1.9749727 | I4: 1.9840993 | J4: 1.7519027 | K4: 1.5196056 | L4: 1.2872133
A5: 4 | B5: 1.8828888 | C5: 1.9029913 | D5: 1.9221392 | E5: 1.9403296 | F5: 1.9555407 | G5: 1.9687204 | H5: 1.978199 | I5: 1.9873285 | J5: 0.21941853 | K5: 0.45139885 | L5: 0.6832628
A6: 40 | B6: 1.8818121 | C6: 1.9019127 | D6: 1.9210607 | E6: 1.9392481 | F6: 1.9544592 | G6: 1.967638 | H6: 1.9771156 | I6: 1.9862442 | J6: 1.7540121 | K6: 1.5216808 | L6: 1.2892551
A7: 5 | B7: 1.8850174 | C7: 1.9051228 | D7: 1.9242744 | E7: 1.9424667 | F7: 1.9576807 | G7: 1.9708633 | H7: 1.9803429 | I7: 1.9894733 | J7: 0.22159958 | K7: 0.4536171 | L7: 0.6855192
A8: 39 | B8: 1.8828764 | C8: 1.8823863 | D8: 1.8809156 | E8: 1.8784647 | F8: 1.8754987 | G8: 1.8721428 | H8: 1.8692169 | I8: 1.8659381 | J8: 1.6356516 | K8: 1.4052038 | L8: 1.1746063
A9: 0 | B9: 1.8860817 | C9: 1.8855915 | D9: 1.884121 | E9: 1.88167 | F9: 1.8787022 | G9: 1.8753471 | H9: 1.8724194 | I9: 1.8691405 | J9: 0.099256516 | K9: 0.32919788 | L9: 0.55895233
A10: 38 | B10: 1.8818121 | C10: 1.8607607 | D10: 1.8387632 | E10: 1.8158226 | F10: 1.7948618 | G10: 1.775178 | H10: 1.7600249 | I10: 1.7445383 | J10: 1.516182 | K10: 1.2876062 | L10: 1.0588217
A11: 1 | B11: 1.8850174 | C11: 1.8639611 | D11: 1.841959 | E11: 1.8190136 | F11: 1.798048 | G11: 1.7783594 | H11: 1.7632036 | I11: 1.7477132 | J11: 1.9758368 | K11: 0.20372105 | L11: 0.43135166
A12: 37 | B12: 1.8796844 | C12: 1.858635 | D12: 1.8366404 | E12: 1.8137053 | F12: 1.7927465 | G12: 1.7730656 | H12: 1.7579145 | I12: 1.7424307 | J12: 1.5141068 | K12: 1.2855635 | L12: 1.0568113
A13: 2 | B13: 1.8828888 | C13: 1.8618355 | D13: 1.8398371 | E13: 1.8168945 | F13: 1.7959318 | G13: 1.7762461 | H13: 1.7610922 | I13: 1.7456055 | J13: 1.9736948 | K13: 0.20154381 | L13: 0.42913723
... A73: 26 | B73: 1.8780174 | C73: 1.8544998 | D73: 1.8300438 | E73: 1.8046551 | F73: 1.7815456 | G73: 1.7599163 | H73: 1.7433082 | I73: 1.7263699 | J73: 1.9164038 | K73: 0.1050539 | L73: 0.29225922

Sheet square
A1: GPIO
A2: 36 | B2: 1.8786192 | C2: 1.8781289 | D2: 1.8766594 | E2: 1.8742095 | F2: 1.87078 | G2: 1.8663731 | H2: 1.8609875 | I2: 1.8546267 | J2: 1.84729 | K2: 1.8389796 | L2: 1.8296976 | M2: 1.8194456 | N2: 1.8082247 | O2: 1.7960396 | P2: 1.7828912 | Q2: 1.6684351 | R2: 1.5539284 | S2: 1.4393702 | T2: 1.3247641 | U2: 1.2101088 | V2: 1.0954084 | W2: 0.9806633 | X2: 0.8658714 | Y2: 0.75103754 | Z2: 0.6361599 | AA2: 0.52124214 | AB2: 0.40628433 | AC2: 0.29128456 | AD2: 0.1762476 | AE2: 0.061170578 | AF2: 1.9460564 | AG2: 1.830908 | AH2: 1.7157211 | AI2: 1.6005001 | AJ2: 1.4852467 | AK2: 1.4965649 | AL2: 1.5070515 | AM2: 1.5167065 | AN2: 1.525524 | AO2: 1.5335083 | AP2: 1.5406532 | AQ2: 1.5469626 | AR2: 1.552433 | AS2: 1.5570602 | AT2: 1.5608482 | AU2: 1.5637951 | AV2: 1.5659008 | AW2: 1.5671635 | AX2: 1.567585 | AY2: 1.5671635 | AZ2: 1.5659008 | BA2: 1.5637951 | BB2: 1.5608482 | BC2: 1.5570602 | BD2: 1.552433 | BE2: 1.5469626 | BF2: 1.5406532 | BG2: 1.5335083 | BH2: 1.525524 | BI2: 1.5167065 | BJ2: 1.5070515 | BK2: 1.4965649 | BL2: 1.4852467 | BM2: 1.6005001 | BN2: 1.7157211 | BO2: 1.830908 | BP2: 1.9460564 | BQ2: 0.061170578 | BR2: 0.1762476 | BS2: 0.29128456 | BT2: 0.40628433 | BU2: 0.52124405 | BV2: 0.6361599 | BW2: 0.75103754 | BX2: 0.8658714 | BY2: 0.9806633 | BZ2: 1.0954084 | CA2: 1.2101107 | CB2: 1.3247641 | CC2: 1.4393702 | CD2: 1.5539284 | CE2: 1.6684351 | CF2: 1.7828912 | CG2: 1.7960396 | CH2: 1.8082247 | CI2: 1.8194456 | CJ2: 1.8296976 | CK2: 1.8389796 | CL2: 1.84729 | CM2: 1.8546267 | CN2: 1.8609875 | CO2: 1.8663731 | CP2: 1.87078 | CQ2: 1.8742095 | CR2: 1.8766594 | CS2: 1.8781289 | CT2: 1.8786192
A3: 3 | B3: 1.8818245 | C3: 1.8813334 | D3: 1.8798639 | E3: 1.8774128 | F3: 1.8739843 | G3: 1.8695745 | H3: 1.8641882 | I3: 1.8578262 | J3: 1.8504878 | K3: 1.8421755 | L3: 1.8328916 | M3: 1.8226365 | N3: 1.8114138 | O3: 1.7992258 | P3: 1.7860736 | Q3: 1.9004765 | R3: 0.014824867 | S3: 0.12911701 | T3: 0.24335384 | U3: 0.3575325 | V3: 0.47165108 | W3: 0.5857086 | X3: 0.6997051 | Y3: 0.8136368 | Z3: 0.9275016 | AA3: 1.0413008 | AB3: 1.1550293 | AC3: 1.2686872 | AD3: 1.3822709 | AE3: 1.49578 | AF3: 1.6092119 | AG3: 1.7225647 | AH3: 1.8358355 | AI3: 1.9490232 | AJ3: 0.062124256 | AK3: 0.077786446 | AL3: 0.09230614 | AM3: 0.10568142 | AN3: 0.11790562 | AO3: 0.12897778 | AP3: 0.13889217 | AQ3: 0.1476469 | AR3: 0.1552391 | AS3: 0.16166782 | AT3: 0.16693115 | AU3: 0.17102528 | AV3: 0.17395116 | AW3: 0.17570686 | AX3: 0.17629242 | AY3: 0.17570686 | AZ3: 0.17395116 | BA3: 0.17102528 | BB3: 0.16693115 | BC3: 0.16166782 | BD3: 0.1552391 | BE3: 0.1476469 | BF3: 0.13889122 | BG3: 0.12897778 | BH3: 0.11790562 | BI3: 0.10568142 | BJ3: 0.09230614 | BK3: 0.077786446 | BL3: 0.062124256 | BM3: 1.9490232 | BN3: 1.8358355 | BO3: 1.7225647 | BP3: 1.6092119 | BQ3: 1.49578 | BR3: 1.3822709 | BS3: 1.2686863 | BT3: 1.1550293 | BU3: 1.0413008 | BV3: 0.9275016 | BW3: 0.8136368 | BX3: 0.6997051 | BY3: 0.5857086 | BZ3: 0.47165108 | CA3: 0.35753155 | CB3: 0.24335384 | CC3: 0.12911701 | CD3: 0.014824867 | CE3: 1.9004765 | CF3: 1.7860736 | CG3: 1.7992258 | CH3: 1.8114138 | CI3: 1.8226365 | CJ3: 1.8328916 | CK3: 1.8421755 | CL3: 1.8504878 | CM3: 1.8578262 | CN3: 1.8641882 | CO3: 1.8695745 | CP3: 1.8739843 | CQ3: 1.8774128 | CR3: 1.8798639 | CS3: 1.8813334 | CT3: 1.8818245
A4: 41 | B4: 1.8796835 | C4: 1.8997812 | D4: 1.9189262 | E4: 1.9371119 | F4: 1.9543352 | G4: 1.9705935 | H4: 1.9858837 | I4: 0.000201 | J4: 0.013544082 | K4: 0.02590847 | L4: 0.03729248 | M4: 0.047694203 | N4: 0.05711174 | O4: 0.06554222 | P4: 0.072981834 | Q4: 1.9561616 | R4: 1.8393278 | S4: 1.7224808 | T4: 1.6056194 | U4: 1.4887457 | V4: 1.3718616 | W4: 1.2549639 | X4: 1.1380539 | Y4: 1.0211325 | Z4: 0.90420055 | AA4: 0.78725624 | AB4: 0.67030334 | AC4: 0.55333805 | AD4: 0.4363642 | AE4: 0.31937885 | AF4: 0.20238209 | AG4: 0.08537864 | AH4: 1.9683647 | AI4: 1.8513412 | AJ4: 1.7343102 | AK4: 1.7279376 | AL4: 1.7207184 | AM4: 1.7126523 | AN4: 1.703741 | AO4: 1.6939869 | AP4: 1.6833897 | AQ4: 1.6719494 | AR4: 1.6596717 | AS4: 1.6465569 | AT4: 1.6326084 | AU4: 1.6178246 | AV4: 1.602211 | AW4: 1.5857677 | AX4: 1.5685005 | AY4: 1.5504093 | AZ4: 1.531496 | BA4: 1.5117664 | BB4: 1.4912224 | BC4: 1.4698658 | BD4: 1.4477024 | BE4: 1.4247304 | BF4: 1.4009571 | BG4: 1.3763866 | BH4: 1.3510208 | BI4: 1.3248634 | BJ4: 1.2979164 | BK4: 1.2701893 | BL4: 1.2416782 | BM4: 1.3552456 | BN4: 1.4687558 | BO4: 1.5822105 | BP4: 1.6956024 | BQ4: 1.8089352 | BR4: 1.9222069 | BS4: 0.035413742 | BT4: 0.14855766 | BU4: 0.26163292 | BV4: 0.37464142 | BW4: 0.48758224 | BX4: 0.60045147 | BY4: 0.71324825 | BZ4: 0.8259735 | CA4: 0.9386225 | CB4: 1.0511923 | CC4: 1.1636858 | CD4: 1.2760984 | CE4: 1.3884277 | CF4: 1.5006741 | CG4: 1.5336342 | CH4: 1.5657111 | CI4: 1.5968992 | CJ4: 1.6271905 | CK4: 1.6565819 | CL4: 1.6850662 | CM4: 1.712639 | CN4: 1.7392942 | CO4: 1.765027 | CP4: 1.789832 | CQ4: 1.8137045 | CR4: 1.8366404 | CS4: 1.858635 | CT4: 1.8796835
A5: 4 | B5: 1.8828888 | C5: 1.9029913 | D5: 1.9221392 | E5: 1.9403296 | F5: 1.9575567 | G5: 1.9738188 | H5: 1.9891129 | I5: 0.003434181 | J5: 0.016778946 | K5: 0.029147148 | L5: 0.040534016 | M5: 0.050937653 | N5: 0.060357094 | O5: 0.06878948 | P5: 0.07623196 | Q5: 0.19303799 | R5: 0.30982876 | S5: 0.42660618 | T5: 0.5433674 | U5: 0.66011524 | V5: 0.7768431 | W5: 0.8935585 | X5: 1.0102549 | Y5: 1.126935 | Z5: 1.2435961 | AA5: 1.36024 | AB5: 1.4768647 | AC5: 1.5934707 | AD5: 1.7100563 | AE5: 1.8266212 | AF5: 1.9431648 | AG5: 0.059687614 | AH5: 0.17618752 | AI5: 0.29266548 | AJ5: 0.4091196 | AK5: 0.40017986 | AL5: 0.39005566 | AM5: 0.378747 | AN5: 0.36626053 | AO5: 0.35260007 | AP5: 0.33776855 | AQ5: 0.3217697 | AR5: 0.3046093 | AS5: 0.28629208 | AT5: 0.26682568 | AU5: 0.24621296 | AV5: 0.22445965 | AW5: 0.20157433 | AX5: 0.17756176 | AY5: 0.15243053 | AZ5: 0.12618637 | BA5: 0.09883785 | BB5: 0.0703907 | BC5: 0.040854454 | BD5: 0.010235786 | BE5: 1.9785452 | BF5: 1.9457884 | BG5: 1.9119749 | BH5: 1.8771151 | BI5: 1.841217 | BJ5: 1.8042879 | BK5: 1.7663403 | BL5: 1.7273828 | BM5: 1.6173382 | BN5: 1.5071545 | BO5: 1.3968393 | BP5: 1.2863894 | BQ5: 1.1758127 | BR5: 1.0651112 | BS5: 0.95428663 | BT5: 0.84334564 | BU5: 0.73228836 | BV5: 0.62111855 | BW5: 0.50983906 | BX5: 0.39845183 | BY5: 0.28695965 | BZ5: 0.17536639 | CA5: 0.06367302 | CB5: 1.9518833 | CC5: 1.8399982 | CD5: 1.7280197 | CE5: 1.6159515 | CF5: 1.5037956 | CG5: 1.5367632 | CH5: 1.5688467 | CI5: 1.6000414 | CJ5: 1.6303395 | CK5: 1.6597366 | CL5: 1.6882277 | CM5: 1.715805 | CN5: 1.7424669 | CO5: 1.7682056 | CP5: 1.7930164 | CQ5: 1.8168945 | CR5: 1.8398361 | CS5: 1.8618355 | CT5: 1.8828888
A6: 40 | B6: 1.8818121 | C6: 1.9019127 | D6: 1.9210607 | E6: 1.9392481 | F6: 1.9564753 | G6: 1.9727354 | H6: 1.9880276 | I6: 0.002347946 | J6: 0.01569271 | K6: 0.028059008 | L6: 0.039445877 | M6: 0.049848557 | N6: 0.059267998 | O6: 0.06769848 | P6: 0.07514095 | Q6: 1.9583015 | R6: 1.8414507 | S6: 1.7245855 | T6: 1.607707 | U6: 1.490817 | V6: 1.3739158 | W6: 1.2570019 | X6: 1.1400776 | Y6: 1.02314 | Z6: 0.9061918 | AA6: 0.78923225 | AB6: 0.67226505 | AC6: 0.55528355 | AD6: 0.43829536 | AE6: 0.32129574 | AF6: 0.20428658 | AG6: 0.08726692 | AH6: 1.9702396 | AI6: 1.8532028 | AJ6: 1.7361583 | AK6: 1.7297859 | AL6: 1.7225647 | AM6: 1.7144985 | AN6: 1.7055855 | AO6: 1.6958294 | AP6: 1.6852303 | AQ6: 1.67379 | AR6: 1.6615124 | AS6: 1.6483955 | AT6: 1.6344433 | AU6: 1.6196594 | AV6: 1.604042 | AW6: 1.5875988 | AX6: 1.5703297 | AY6: 1.5522364 | AZ6: 1.5333214 | BA6: 1.5135899 | BB6: 1.4930439 | BC6: 1.4716853 | BD6: 1.4495182 | BE6: 1.4265442 | BF6: 1.4027691 | BG6: 1.3781948 | BH6: 1.3528272 | BI6: 1.3266659 | BJ6: 1.299717 | BK6: 1.271986 | BL6: 1.243473 | BM6: 1.3570518 | BN6: 1.4705753 | BO6: 1.5840397 | BP6: 1.6974467 | BQ6: 1.810793 | BR6: 1.9240761 | BS6: 0.037296295 | BT6: 0.15045261 | BU6: 0.26354408 | BV6: 0.37656498 | BW6: 0.48951912 | BX6: 0.6024027 | BY6: 0.7152156 | BZ6: 0.8279543 | CA6: 0.94061756 | CB6: 1.0532036 | CC6: 1.1657124 | CD6: 1.2781392 | CE6: 1.3904848 | CF6: 1.5027466 | CG6: 1.5357122 | CH6: 1.5677929 | CI6: 1.5989857 | CJ6: 1.629281 | CK6: 1.6586771 | CL6: 1.6871653 | CM6: 1.7147427 | CN6: 1.7414016 | CO6: 1.7671374 | CP6: 1.7919475 | CQ6: 1.8158226 | CR6: 1.8387632 | CS6: 1.8607607 | CT6: 1.8818121
A7: 5 | B7: 1.8850174 | C7: 1.9051228 | D7: 1.9242744 | E7: 1.9424667 | F7: 1.9596978 | G7: 1.9759626 | H7: 1.9912577 | I7: 0.005580903 | J7: 0.018928528 | K7: 0.031297684 | L7: 0.042687416 | M7: 0.053092957 | N7: 0.06251335 | O7: 0.07094669 | P7: 0.07839012 | Q7: 0.19521523 | R7: 0.31202507 | S7: 0.42882064 | T7: 0.54560184 | U7: 0.6623678 | V7: 0.7791176 | W7: 0.89585114 | X7: 1.0125685 | Y7: 1.1292696 | Z7: 1.2459526 | AA7: 1.3626175 | AB7: 1.4792652 | AC7: 1.5958939 | AD7: 1.7125015 | AE7: 1.8290901 | AF7: 1.9456578 | AG7: 0.062205315 | AH7: 0.17873001 | AI7: 0.29523277 | AJ7: 0.41171265 | AK7: 0.402771 | AL7: 0.39264393 | AM7: 0.3813343 | AN7: 0.36884502 | AO7: 0.35518077 | AP7: 0.34034538 | AQ7: 0.32434365 | AR7: 0.30717945 | AS7: 0.28885937 | AT7: 0.26938725 | AU7: 0.24876978 | AV7: 0.22701263 | AW7: 0.20412254 | AX7: 0.18010521 | AY7: 0.15496731 | AZ7: 0.12871838 | BA7: 0.10136318 | BB7: 0.07291031 | BC7: 0.043367382 | BD7: 0.012742996 | BE7: 1.9810457 | BF7: 1.9482814 | BG7: 1.9144621 | BH7: 1.8795937 | BI7: 1.843689 | BJ7: 1.8067532 | BK7: 1.7687978 | BL7: 1.7298317 | BM7: 1.6197654 | BN7: 1.5095606 | BO7: 1.3992232 | BP7: 1.2887534 | BQ7: 1.1781559 | BR7: 1.0674343 | BS7: 0.95659065 | BT7: 0.8456297 | BU7: 0.7345543 | BV7: 0.62336445 | BW7: 0.51206684 | BX7: 0.40066242 | BY7: 0.28915215 | BZ7: 0.17754078 | CA7: 0.06582928 | CB7: 1.9540234 | CC7: 1.8421211 | CD7: 1.7301254 | CE7: 1.618042 | CF7: 1.505868 | CG7: 1.5388412 | CH7: 1.5709295 | CI7: 1.602128 | CJ7: 1.6324311 | CK7: 1.6618328 | CL7: 1.6903275 | CM7: 1.7179098 | CN7: 1.7445755 | CO7: 1.7703171 | CP7: 1.7951326 | CQ7: 1.8190136 | CR7: 1.841959 | CS7: 1.8639611 | CT7: 1.8850174
A8: 39 | B8: 1.8828764 | C8: 1.8823863 | D8: 1.8809156 | E8: 1.8784647 | F8: 1.8750353 | G8: 1.8706255 | H8: 1.8652391 | I8: 1.8588772 | J8: 1.8515377 | K8: 1.8432255 | L8: 1.8339405 | M8: 1.8236847 | N8: 1.8124619 | O8: 1.8002719 | P8: 1.7871199 | Q8: 1.6726294 | R8: 1.5580893 | S8: 1.4434986 | T8: 1.3288603 | U8: 1.2141743 | V8: 1.0994425 | W8: 0.9846649 | X8: 0.8698435 | Y8: 0.75497913 | Z8: 0.6400728 | AA8: 0.5251255 | AB8: 0.41013908 | AC8: 0.29511166 | AD8: 0.18004608 | AE8: 0.06494236 | AF8: 1.9498005 | AG8: 1.8346252 | AH8: 1.7194138 | AI8: 1.6041659 | AJ8: 1.4888859 | AK8: 1.5002079 | AL8: 1.5106963 | AM8: 1.5203533 | AN8: 1.5291747 | AO8: 1.537157 | AP8: 1.5443057 | AQ8: 1.5506153 | AR8: 1.5560856 | AS8: 1.5607147 | AT8: 1.5645065 | AU8: 1.5674534 | AV8: 1.5695591 | AW8: 1.5708218 | AX8: 1.5712452 | AY8: 1.5708218 | AZ8: 1.5695591 | BA8: 1.5674534 | BB8: 1.5645065 | BC8: 1.5607147 | BD8: 1.5560856 | BE8: 1.5506153 | BF8: 1.5443057 | BG8: 1.537157 | BH8: 1.5291747 | BI8: 1.5203533 | BJ8: 1.5106963 | BK8: 1.5002079 | BL8: 1.4888859 | BM8: 1.6041659 | BN8: 1.7194138 | BO8: 1.8346252 | BP8: 1.9498005 | BQ8: 0.06494236 | BR8: 0.18004608 | BS8: 0.29511166 | BT8: 0.41013908 | BU8: 0.5251274 | BV8: 0.6400728 | BW8: 0.75497913 | BX8: 0.8698435 | BY8: 0.9846649 | BZ8: 1.0994425 | CA8: 1.2141743 | CB8: 1.3288603 | CC8: 1.4434986 | CD8: 1.5580893 | CE8: 1.6726294 | CF8: 1.7871199 | CG8: 1.8002719 | CH8: 1.8124619 | CI8: 1.8236847 | CJ8: 1.8339405 | CK8: 1.8432255 | CL8: 1.8515377 | CM8: 1.8588772 | CN8: 1.8652391 | CO8: 1.8706255 | CP8: 1.8750353 | CQ8: 1.8784647 | CR8: 1.8809156 | CS8: 1.8823863 | CT8: 1.8828764
A9: 0 | B9: 1.8860817 | C9: 1.8855915 | D9: 1.884121 | E9: 1.88167 | F9: 1.8782396 | G9: 1.8738298 | H9: 1.8684416 | I9: 1.8620768 | J9: 1.8547363 | K9: 1.8464222 | L9: 1.8371353 | M9: 1.8268765 | N9: 1.8156509 | O9: 1.8034592 | P9: 1.7903032 | Q9: 1.9047402 | R9: 0.019123077 | S9: 0.13345051 | T9: 0.24772358 | U9: 0.36193943 | V9: 0.4760952 | W9: 0.5901909 | X9: 0.7042246 | Y9: 0.81819534 | Z9: 0.93210036 | AA9: 1.0459394 | AB9: 1.159709 | AC9: 1.2734089 | AD9: 1.3870344 | AE9: 1.5005875 | AF9: 1.6140642 | AG9: 1.7274609 | AH9: 1.8407764 | AI9: 1.9540119 | AJ9: 0.06716061 | AK9: 0.082829475 | AL9: 0.09735584 | AM9: 0.11073589 | AN9: 0.1229658 | AO9: 0.13404179 | AP9: 0.14396 | AQ9: 0.1527195 | AR9: 0.16031551 | AS9: 0.16674614 | AT9: 0.17201139 | AU9: 0.1761074 | AV9: 0.17903519 | AW9: 0.18079092 | AX9: 0.18137647 | AY9: 0.18079092 | AZ9: 0.17903519 | BA9: 0.1761074 | BB9: 0.17201139 | BC9: 0.16674614 | BD9: 0.16031551 | BE9: 0.1527195 | BF9: 0.14396095 | BG9: 0.13404179 | BH9: 0.1229658 | BI9: 0.11073589 | BJ9: 0.09735584 | BK9: 0.082829475 | BL9: 0.06716061 | BM9: 1.9540119 | BN9: 1.8407774 | BO9: 1.7274609 | BP9: 1.6140642 | BQ9: 1.5005875 | BR9: 1.3870354 | BS9: 1.2734079 | BT9: 1.1597099 | BU9: 1.0459394 | BV9: 0.93210036 | BW9: 0.8181963 | BX9: 0.7042246 | BY9: 0.5901909 | BZ9: 0.4760952 | CA9: 0.36193848 | CB9: 0.24772455 | CC9: 0.13345146 | CD9: 0.019123077 | CE9: 1.9047402 | CF9: 1.7903032 | CG9: 1.8034592 | CH9: 1.8156509 | CI9: 1.8268765 | CJ9: 1.8371353 | CK9: 1.8464222 | CL9: 1.8547372 | CM9: 1.8620768 | CN9: 1.8684416 | CO9: 1.8738298 | CP9: 1.8782396 | CQ9: 1.88167 | CR9: 1.884121 | CS9: 1.8855915 | CT9: 1.8860817
A10: 38 | B10: 1.8818121 | C10: 1.8607607 | D10: 1.8387632 | E10: 1.8158226 | F10: 1.7919475 | G10: 1.7671374 | H10: 1.7414016 | I10: 1.7147427 | J10: 1.6871653 | K10: 1.6586771 | L10: 1.629281 | M10: 1.5989857 | N10: 1.5677929 | O10: 1.5357122 | P10: 1.5027466 | Q10: 1.3904848 | R10: 1.2781392 | S10: 1.1657124 | T10: 1.0532036 | U10: 0.94061756 | V10: 0.8279543 | W10: 0.7152156 | X10: 0.6024027 | Y10: 0.48951912 | Z10: 0.37656498 | AA10: 0.26354218 | AB10: 0.15045261 | AC10: 0.037296295 | AD10: 1.9240761 | AE10: 1.810793 | AF10: 1.6974467 | AG10: 1.5840397 | AH10: 1.4705753 | AI10: 1.3570518 | AJ10: 1.243473 | AK10: 1.271986 | AL10: 1.299717 | AM10: 1.3266659 | AN10: 1.3528272 | AO10: 1.3781948 | AP10: 1.4027691 | AQ10: 1.4265442 | AR10: 1.4495182 | AS10: 1.4716853 | AT10: 1.4930439 | AU10: 1.5135899 | AV10: 1.5333214 | AW10: 1.5522364 | AX10: 1.5703297 | AY10: 1.5875988 | AZ10: 1.604042 | BA10: 1.6196594 | BB10: 1.6344433 | BC10: 1.6483955 | BD10: 1.6615124 | BE10: 1.67379 | BF10: 1.6852303 | BG10: 1.6958294 | BH10: 1.7055855 | BI10: 1.7144985 | BJ10: 1.7225647 | BK10: 1.7297859 | BL10: 1.7361583 | BM10: 1.8532028 | BN10: 1.9702396 | BO10: 0.08726692 | BP10: 0.20428658 | BQ10: 0.32129574 | BR10: 0.43829536 | BS10: 0.55528355 | BT10: 0.67226505 | BU10: 0.78923416 | BV10: 0.9061918 | BW10: 1.02314 | BX10: 1.1400776 | BY10: 1.2570019 | BZ10: 1.3739158 | CA10: 1.490818 | CB10: 1.607707 | CC10: 1.7245855 | CD10: 1.8414507 | CE10: 1.9583015 | CF10: 0.07514095 | CG10: 0.06769848 | CH10: 0.059267998 | CI10: 0.049848557 | CJ10: 0.039445877 | CK10: 0.028059008 | CL10: 0.01569271 | CM10: 0.002347946 | CN10: 1.9880276 | CO10: 1.9727354 | CP10: 1.9564753 | CQ10: 1.9392481 | CR10: 1.9210607 | CS10: 1.9019127 | CT10: 1.8818121
A11: 1 | B11: 1.8850174 | C11: 1.8639611 | D11: 1.841959 | E11: 1.8190136 | F11: 1.7951326 | G11: 1.7703171 | H11: 1.7445755 | I11: 1.7179098 | J11: 1.6903275 | K11: 1.6618328 | L11: 1.6324311 | M11: 1.602128 | N11: 1.5709295 | O11: 1.5388412 | P11: 1.505868 | Q11: 1.618042 | R11: 1.7301254 | S11: 1.8421211 | T11: 1.9540234 | U11: 0.06583023 | V11: 0.17754078 | W11: 0.28915215 | X11: 0.40066242 | Y11: 0.51206684 | Z11: 0.62336445 | AA11: 0.7345543 | AB11: 0.8456297 | AC11: 0.95659155 | AD11: 1.0674343 | AE11: 1.1781559 | AF11: 1.2887534 | AG11: 1.3992232 | AH11: 1.5095606 | AI11: 1.6197654 | AJ11: 1.7298317 | AK11: 1.7687969 | AL11: 1.8067532 | AM11: 1.843689 | AN11: 1.8795937 | AO11: 1.9144621 | AP11: 1.9482814 | AQ11: 1.9810447 | AR11: 0.012742996 | AS11: 0.043367382 | AT11: 0.07291031 | AU11: 0.10136318 | AV11: 0.12871838 | AW11: 0.15496731 | AX11: 0.18010521 | AY11: 0.20412254 | AZ11: 0.22701263 | BA11: 0.24876978 | BB11: 0.26938725 | BC11: 0.28885937 | BD11: 0.30717945 | BE11: 0.32434365 | BF11: 0.34034538 | BG11: 0.35518077 | BH11: 0.36884502 | BI11: 0.3813343 | BJ11: 0.39264393 | BK11: 0.402771 | BL11: 0.41171265 | BM11: 0.29523277 | BN11: 0.17873001 | BO11: 0.062205315 | BP11: 1.9456578 | BQ11: 1.8290901 | BR11: 1.7125015 | BS11: 1.5958929 | BT11: 1.4792652 | BU11: 1.3626175 | BV11: 1.2459526 | BW11: 1.1292696 | BX11: 1.0125685 | BY11: 0.89585114 | BZ11: 0.7791176 | CA11: 0.6623668 | CB11: 0.54560184 | CC11: 0.42882064 | CD11: 0.31202507 | CE11: 0.19521523 | CF11: 0.07839012 | CG11: 0.07094669 | CH11: 0.06251335 | CI11: 0.053092957 | CJ11: 0.042687416 | CK11: 0.031297684 | CL11: 0.018928528 | CM11: 0.005580903 | CN11: 1.9912577 | CO11: 1.9759626 | CP11: 1.9596978 | CQ11: 1.9424667 | CR11: 1.9242744 | CS11: 1.9051228 | CT11: 1.8850174
A12: 37 | B12: 1.8796844 | C12: 1.858635 | D12: 1.8366404 | E12: 1.8137053 | F12: 1.789832 | G12: 1.765027 | H12: 1.7392942 | I12: 1.712639 | J12: 1.6850662 | K12: 1.6565819 | L12: 1.6271905 | M12: 1.5968992 | N12: 1.5657111 | O12: 1.5336342 | P12: 1.5006741 | Q12: 1.3884277 | R12: 1.2760984 | S12: 1.1636858 | T12: 1.0511942 | U12: 0.9386225 | V12: 0.8259735 | W12: 0.71325016 | X12: 0.60045147 | Y12: 0.48758224 | Z12: 0.37464142 | AA12: 0.26163292 | AB12: 0.14855766 | AC12: 0.035413742 | AD12: 1.9222069 | AE12: 1.808937 | AF12: 1.6956043 | AG12: 1.5822105 | AH12: 1.4687576 | AI12: 1.3552456 | AJ12: 1.2416801 | AK12: 1.2701893 | AL12: 1.2979164 | AM12: 1.3248634 | AN12: 1.3510208 | AO12: 1.3763866 | AP12: 1.4009571 | AQ12: 1.4247304 | AR12: 1.4477024 | AS12: 1.4698658 | AT12: 1.4912224 | AU12: 1.5117664 | AV12: 1.531496 | AW12: 1.5504093 | AX12: 1.5685005 | AY12: 1.5857677 | AZ12: 1.602211 | BA12: 1.6178246 | BB12: 1.6326084 | BC12: 1.6465569 | BD12: 1.6596717 | BE12: 1.6719494 | BF12: 1.6833897 | BG12: 1.6939869 | BH12: 1.703741 | BI12: 1.7126523 | BJ12: 1.7207184 | BK12: 1.7279376 | BL12: 1.7343102 | BM12: 1.8513412 | BN12: 1.9683647 | BO12: 0.08537864 | BP12: 0.20238209 | BQ12: 0.31937885 | BR12: 0.4363642 | BS12: 0.55333805 | BT12: 0.67030334 | BU12: 0.78725815 | BV12: 0.90420055 | BW12: 1.0211325 | BX12: 1.1380539 | BY12: 1.2549639 | BZ12: 1.3718616 | CA12: 1.4887466 | CB12: 1.6056194 | CC12: 1.7224808 | CD12: 1.8393278 | CE12: 1.9561616 | CF12: 0.072981834 | CG12: 0.06554222 | CH12: 0.05711174 | CI12: 0.047694203 | CJ12: 0.03729248 | CK12: 0.02590847 | CL12: 0.013544082 | CM12: 0.000201 | CN12: 1.9858837 | CO12: 1.9705944 | CP12: 1.9543352 | CQ12: 1.9371119 | CR12: 1.9189262 | CS12: 1.8997812 | CT12: 1.8796844
A13: 2 | B13: 1.8828888 | C13: 1.8618355 | D13: 1.8398371 | E13: 1.8168945 | F13: 1.7930174 | G13: 1.7682056 | H13: 1.7424669 | I13: 1.715806 | J13: 1.6882277 | K13: 1.6597366 | L13: 1.6303395 | M13: 1.6000414 | N13: 1.5688467 | O13: 1.5367632 | P13: 1.5037956 | Q13: 1.6159515 | R13: 1.7280197 | S13: 1.8399982 | T13: 1.9518833 | U13: 0.06367397 | V13: 0.17536639 | W13: 0.28695965 | X13: 0.39845183 | Y13: 0.50983906 | Z13: 0.62111855 | AA13: 0.73228836 | AB13: 0.84334564 | AC13: 0.9542885 | AD13: 1.0651112 | AE13: 1.1758127 | AF13: 1.2863894 | AG13: 1.3968393 | AH13: 1.5071545 | AI13: 1.6173382 | AJ13: 1.7273828 | AK13: 1.7663412 | AL13: 1.8042889 | AM13: 1.841217 | AN13: 1.8771151 | AO13: 1.9119749 | AP13: 1.9457884 | AQ13: 1.9785452 | AR13: 0.010235786 | AS13: 0.040854454 | AT13: 0.070391655 | AU13: 0.09883785 | AV13: 0.12618732 | AW13: 0.15243053 | AX13: 0.17756271 | AY13: 0.20157433 | AZ13: 0.2244606 | BA13: 0.24621296 | BB13: 0.26682568 | BC13: 0.28629303 | BD13: 0.3046093 | BE13: 0.3217697 | BF13: 0.33776855 | BG13: 0.35260007 | BH13: 0.36626053 | BI13: 0.378747 | BJ13: 0.39005566 | BK13: 0.40017986 | BL13: 0.4091196 | BM13: 0.29266548 | BN13: 0.17618752 | BO13: 0.059687614 | BP13: 1.9431648 | BQ13: 1.8266212 | BR13: 1.7100563 | BS13: 1.5934696 | BT13: 1.4768647 | BU13: 1.36024 | BV13: 1.2435961 | BW13: 1.126935 | BX13: 1.0102549 | BY13: 0.8935585 | BZ13: 0.7768431 | CA13: 0.66011333 | CB13: 0.5433674 | CC13: 0.42660618 | CD13: 0.30982876 | CE13: 0.19303799 | CF13: 0.07623196 | CG13: 0.06878948 | CH13: 0.060357094 | CI13: 0.050937653 | CJ13: 0.040534016 | CK13: 0.029147148 | CL13: 0.016778946 | CM13: 0.003434181 | CN13: 1.9891129 | CO13: 1.9738197 | CP13: 1.9575577 | CQ13: 1.9403296 | CR13: 1.9221401 | CS13: 1.9029913 | CT13: 1.8828888
... A73: 26 | B73: 1.8780174 | C73: 1.8544998 | D73: 1.8300438 | E73: 1.8046551 | F73: 1.7783383 | G73: 1.7510996 | H73: 1.7229424 | I73: 1.6938745 | J73: 1.6638986 | K73: 1.6330223 | L73: 1.6012506 | M73: 1.5685911 | N73: 1.5350475 | O73: 1.5006266 | P73: 1.4653349 | Q73: 1.5588007 | R73: 1.6519108 | S73: 1.7446594 | T73: 1.8370372 | U73: 1.9290379 | V73: 0.020653725 | W73: 0.11187839 | X73: 0.20270252 | Y73: 0.29311848 | Z73: 0.38311768 | AA73: 0.47269344 | AB73: 0.5618353 | AC73: 0.6505375 | AD73: 0.7387876 | AE73: 0.8265791 | AF73: 0.91390127 | AG73: 1.0007458 | AH73: 1.0871019 | AI73: 1.1729612 | AJ73: 1.2583122 | AK73: 1.2985849 | AL73: 1.3378925 | AM73: 1.3762254 | AN73: 1.4135752 | AO73: 1.4499341 | AP73: 1.4852924 | AQ73: 1.5196419 | AR73: 1.5529728 | AS73: 1.5852795 | AT73: 1.6165522 | AU73: 1.6467848 | AV73: 1.6759683 | AW73: 1.7040948 | AX73: 1.7311572 | AY73: 1.7571487 | AZ73: 1.7820636 | BA73: 1.8058939 | BB73: 1.8286341 | BC73: 1.850277 | BD73: 1.8708172 | BE73: 1.8902491 | BF73: 1.9085684 | BG73: 1.9257689 | BH73: 1.9418449 | BI73: 1.9567949 | BJ73: 1.9706116 | BK73: 1.9832926 | BL73: 1.994834 | BM73: 1.9042845 | BN73: 1.8132716 | BO73: 1.7218065 | BP73: 1.6299 | BQ73: 1.5375595 | BR73: 1.4447945 | BS73: 1.3516177 | BT73: 1.2580357 | BU73: 1.1640568 | BV73: 1.0696917 | BW73: 0.974946 | BX73: 0.8798313 | BY73: 0.78435326 | BZ73: 0.6885195 | CA73: 0.5923395 | CB73: 0.49581814 | CC73: 0.39896488 | CD73: 0.30178642 | CE73: 0.20428944 | CF73: 0.10647965 | CG73: 0.096505165 | CH73: 0.085544586 | CI73: 0.073596954 | CJ73: 0.060667038 | CK73: 0.04675865 | CL73: 0.031871796 | CM73: 0.016011238 | CN73: 1.9991797 | CO73: 1.9813814 | CP73: 1.9626198 | CQ73: 1.9428988 | CR73: 1.9222212 | CS73: 1.900592 | CT73: 1.8780174

Sheet circle
A1: GPIO
A2: 36 | B2: 0.70006084 | C2: 0.7904968 | D2: 0.8808593 | E2: 0.97045606 | F2: 1.0585785 | G2: 1.1445198 | H2: 1.2275763 | I2: 1.3070526 | J2: 1.3822699 | K2: 1.4525747 | L2: 1.5173454 | M2: 1.5759983 | N2: 1.6279964 | O2: 1.6728582 | P2: 1.7101641 | Q2: 1.7395554 | R2: 1.7607555 | S2: 1.7735586 | T2: 1.7778397 | U2: 1.7735577 | V2: 1.7607555 | W2: 1.7395554 | X2: 1.710163 | Y2: 1.6728582 | Z2: 1.6279964 | AA2: 1.5759974 | AB2: 1.5173446 | AC2: 1.4525747 | AD2: 1.3822689 | AE2: 1.3070517 | AF2: 1.2275753 | AG2: 1.1445189 | AH2: 1.0585775 | AI2: 0.97045517 | AJ2: 0.8808593 | AK2: 0.79049486 | AL2: 0.70005894 | AM2: 0.6102333 | AN2: 0.5216837 | AO2: 0.43505192 | AP2: 0.35095406 | AQ2: 0.26997757 | AR2: 0.19268131 | AS2: 0.11958504 | AT2: 0.05117416 | AU2: 1.9878988 | AV2: 1.9301661 | AW2: 1.8783485 | AX2: 1.6279964 | AY2: 1.6728573 | AZ2: 1.7101622 | BA2: 1.7395554 | BB2: 1.7607546 | BC2: 1.7735577 | BD2: 1.7778387 | BE2: 1.7735577 | BF2: 1.7607546 | BG2: 1.7395554 | BH2: 1.710163 | BI2: 1.6728582 | BJ2: 1.6279964 | BK2: 1.5759974 | BL2: 1.5173446 | BM2: 1.4525737 | BN2: 1.3822689 | BO2: 1.3070517 | BP2: 1.2275743 | BQ2: 1.1445179 | BR2: 1.0585775 | BS2: 0.97045326 | BT2: 0.8808584 | BU2: 0.79049397 | BV2: 0.700057
A3: 3 | B3: 1.4323004 | C3: 1.5048122 | D3: 1.5770874 | E3: 1.648571 | F3: 1.7187023 | G3: 1.7869301 | H3: 1.8527088 | I3: 1.9155006 | J3: 1.9747906 | K3: 0.030086517 | L3: 0.08092594 | M3: 0.12687588 | N3: 0.1675415 | O3: 0.20257376 | P3: 0.23166753 | Q3: 0.2545643 | R3: 0.2710657 | S3: 0.28102684 | T3: 0.28435612 | U3: 0.28102684 | V3: 0.2710657 | W3: 0.2545643 | X3: 0.23166753 | Y3: 0.20257376 | Z3: 0.1675415 | AA3: 0.12687588 | AB3: 0.08092594 | AC3: 0.030086517 | AD3: 1.9747887 | AE3: 1.9154987 | AF3: 1.852707 | AG3: 1.7869301 | AH3: 1.7187023 | AI3: 1.6485692 | AJ3: 1.5770855 | AK3: 1.5048122 | AL3: 1.4323004 | AM3: 1.3601055 | AN3: 1.2887688 | AO3: 1.2188187 | AP3: 1.1507645 | AQ3: 1.085104 | AR3: 1.0223007 | AS3: 0.962801 | AT3: 0.90701866 | AU3: 0.8553429 | AV3: 0.80813026 | AW3: 0.76569563 | AX3: 0.1675415 | AY3: 0.20257376 | AZ3: 0.23166753 | BA3: 0.2545643 | BB3: 0.2710657 | BC3: 0.28102684 | BD3: 0.28435612 | BE3: 0.28102684 | BF3: 0.2710657 | BG3: 0.2545643 | BH3: 0.23166753 | BI3: 0.20257376 | BJ3: 0.1675415 | BK3: 0.12687588 | BL3: 0.08092594 | BM3: 0.030086517 | BN3: 1.9747887 | BO3: 1.9154987 | BP3: 1.852707 | BQ3: 1.7869301 | BR3: 1.7187003 | BS3: 1.6485692 | BT3: 1.5770855 | BU3: 1.5048103 | BV3: 1.4322987
A4: 41 | B4: 2.8327723 | C4: 2.8783512 | D4: 2.9301682 | E4: 2.9879007 | F4: 1.0511751 | G4: 1.119586 | H4: 1.1926823 | I4: 1.2699795 | J4: 1.350954 | K4: 1.4350519 | L4: 1.5216837 | M4: 1.6102343 | N4: 1.7000599 | O4: 1.7904959 | P4: 1.8808594 | Q4: 1.9704552 | R4: 2.0585775 | S4: 2.1445198 | T4: 2.2275753 | U4: 2.3070517 | V4: 2.3822699 | W4: 2.4525747 | X4: 2.5173445 | Y4: 2.5759974 | Z4: 2.6279964 | AA4: 2.6728582 | AB4: 2.710163 | AC4: 2.7395554 | AD4: 2.7607546 | AE4: 2.7735577 | AF4: 2.7778397 | AG4: 2.7735577 | AH4: 2.7607546 | AI4: 2.7395554 | AJ4: 2.710163 | AK4: 2.6728582 | AL4: 2.6279964 | AM4: 2.5759974 | AN4: 2.5173445 | AO4: 2.4525747 | AP4: 2.382269 | AQ4: 2.3070517 | AR4: 2.2275763 | AS4: 2.1445198 | AT4: 2.0585775 | AU4: 1.9704552 | AV4: 1.8808594 | AW4: 1.7904949 | AX4: 1.700058 | AY4: 1.7904949 | AZ4: 1.8808584 | BA4: 1.9704542 | BB4: 2.0585775 | BC4: 2.1445189 | BD4: 2.2275743 | BE4: 2.3070507 | BF4: 2.382269 | BG4: 2.4525738 | BH4: 2.5173445 | BI4: 2.5759974 | BJ4: 2.6279955 | BK4: 2.6728573 | BL4: 2.7101622 | BM4: 2.7395554 | BN4: 2.7607546 | BO4: 2.7735567 | BP4: 2.7778387 | BQ4: 2.7735567 | BR4: 2.7607546 | BS4: 2.7395554 | BT4: 2.7101622 | BU4: 2.6728573 | BV4: 2.6279955
A5: 4 | B5: 1.7283306 | C5: 1.7656975 | D5: 1.8081303 | E5: 1.8553448 | F5: 1.9070206 | G5: 1.9628029 | H5: 2.0223007 | I5: 2.085104 | J5: 2.1507645 | K5: 2.2188187 | L5: 2.2887688 | M5: 2.3601055 | N5: 2.4323006 | O5: 2.5048122 | P5: 2.5770855 | Q5: 2.648569 | R5: 2.7187023 | S5: 2.78693 | T5: 2.8527088 | U5: 2.9154987 | V5: 2.9747887 | W5: 1.0300865 | X5: 1.080926 | Y5: 1.1268759 | Z5: 1.1675415 | AA5: 1.2025738 | AB5: 1.2316675 | AC5: 1.2545643 | AD5: 1.2710657 | AE5: 1.2810268 | AF5: 1.2843561 | AG5: 1.2810268 | AH5: 1.2710657 | AI5: 1.2545643 | AJ5: 1.2316675 | AK5: 1.2025738 | AL5: 1.1675415 | AM5: 1.1268768 | AN5: 1.080926 | AO5: 1.0300865 | AP5: 2.9747906 | AQ5: 2.9154987 | AR5: 2.852707 | AS5: 2.78693 | AT5: 2.7187023 | AU5: 2.648569 | AV5: 2.5770874 | AW5: 2.5048122 | AX5: 2.4322987 | AY5: 2.5048103 | AZ5: 2.5770855 | BA5: 2.648569 | BB5: 2.7187023 | BC5: 2.78693 | BD5: 2.852707 | BE5: 2.9154987 | BF5: 2.9747887 | BG5: 1.0300865 | BH5: 1.080926 | BI5: 1.1268759 | BJ5: 1.1675415 | BK5: 1.2025738 | BL5: 1.2316656 | BM5: 1.2545643 | BN5: 1.2710657 | BO5: 1.2810268 | BP5: 1.2843561 | BQ5: 1.2810268 | BR5: 1.2710657 | BS5: 1.2545643 | BT5: 1.2316656 | BU5: 1.2025738 | BV5: 1.1675415
A6: 40 | B6: 2.8327723 | C6: 2.7937202 | D6: 2.7614355 | E6: 2.7361174 | F6: 2.7179232 | G6: 2.7069616 | H6: 2.7033005 | I6: 2.7069616 | J6: 2.7179232 | K6: 2.7361174 | L6: 2.7614346 | M6: 2.7937193 | N6: 2.8327713 | O6: 2.8783503 | P6: 2.9301682 | Q6: 2.9878988 | R6: 1.0511742 | S6: 1.119586 | T6: 1.1926823 | U6: 1.2699785 | V6: 1.350954 | W6: 1.4350519 | X6: 1.5216837 | Y6: 1.6102333 | Z6: 1.7000589 | AA6: 1.7904949 | AB6: 1.8808584 | AC6: 1.9704542 | AD6: 2.0585775 | AE6: 2.1445189 | AF6: 2.2275743 | AG6: 2.3070517 | AH6: 2.382269 | AI6: 2.4525738 | AJ6: 2.5173445 | AK6: 2.5759974 | AL6: 2.6279964 | AM6: 2.6728582 | AN6: 2.7101622 | AO6: 2.7395554 | AP6: 2.7607546 | AQ6: 2.7735586 | AR6: 2.7778397 | AS6: 2.7735577 | AT6: 2.7607546 | AU6: 2.7395554 | AV6: 2.710163 | AW6: 2.6728582 | AX6: 2.8327703 | AY6: 2.8783484 | AZ6: 2.9301662 | BA6: 2.9878979 | BB6: 1.0511732 | BC6: 1.1195831 | BD6: 1.1926804 | BE6: 1.2699766 | BF6: 1.3509531 | BG6: 1.435051 | BH6: 1.5216827 | BI6: 1.6102324 | BJ6: 1.700058 | BK6: 1.790494 | BL6: 1.8808584 | BM6: 1.9704533 | BN6: 2.0585775 | BO6: 2.144518 | BP6: 2.2275734 | BQ6: 2.3070507 | BR6: 2.382267 | BS6: 2.4525728 | BT6: 2.5173435 | BU6: 2.5759964 | BV6: 2.6279945
A7: 5 | B7: 1.7283306 | C7: 1.6962814 | D7: 1.6697655 | E7: 1.6489601 | F7: 1.6340008 | G7: 1.6249847 | H7: 1.621973 | I7: 1.6249847 | J7: 1.6340008 | K7: 1.6489582 | L7: 1.6697655 | M7: 1.6962814 | N7: 1.7283306 | O7: 1.7656956 | P7: 1.8081303 | Q7: 1.8553429 | R7: 1.9070206 | S7: 1.962801 | T7: 2.0223007 | U7: 2.085104 | V7: 2.1507645 | W7: 2.2188187 | X7: 2.2887688 | Y7: 2.3601055 | Z7: 2.4322987 | AA7: 2.5048122 | AB7: 2.5770855 | AC7: 2.648569 | AD7: 2.7187023 | AE7: 2.78693 | AF7: 2.8527088 | AG7: 2.9154987 | AH7: 2.9747887 | AI7: 1.0300865 | AJ7: 1.080926 | AK7: 1.1268759 | AL7: 1.1675415 | AM7: 1.2025738 | AN7: 1.2316656 | AO7: 1.2545643 | AP7: 1.2710657 | AQ7: 1.2810268 | AR7: 1.2843561 | AS7: 1.2810268 | AT7: 1.2710657 | AU7: 1.2545643 | AV7: 1.2316675 | AW7: 1.2025738 | AX7: 1.7283287 | AY7: 1.7656937 | AZ7: 1.8081284 | BA7: 1.8553429 | BB7: 1.9070187 | BC7: 1.962801 | BD7: 2.0223007 | BE7: 2.085104 | BF7: 2.1507645 | BG7: 2.2188187 | BH7: 2.2887669 | BI7: 2.3601055 | BJ7: 2.4322987 | BK7: 2.5048103 | BL7: 2.5770855 | BM7: 2.648569 | BN7: 2.7187004 | BO7: 2.78693 | BP7: 2.852707 | BQ7: 2.9154987 | BR7: 2.9747887 | BS7: 1.0300865 | BT7: 1.080926 | BU7: 1.1268759 | BV7: 1.1675415
A8: 39 | B8: 0.70006084 | C8: 0.61023426 | D8: 0.52168465 | E8: 0.43505287 | F8: 0.35095498 | G8: 0.26997948 | H8: 0.19268322 | I8: 0.11958695 | J8: 0.05117512 | K8: 1.9878998 | L8: 1.9301682 | M8: 1.8783503 | N8: 1.8327713 | O8: 1.7937193 | P8: 1.7614346 | Q8: 1.7361164 | R8: 1.7179221 | S8: 1.7069616 | T8: 1.7032995 | U8: 1.7069616 | V8: 1.7179221 | W8: 1.7361164 | X8: 1.7614346 | Y8: 1.7937182 | Z8: 1.8327705 | AA8: 1.8783493 | AB8: 1.9301672 | AC8: 1.9878988 | AD8: 0.051173206 | AE8: 0.11958504 | AF8: 0.19268131 | AG8: 0.26997757 | AH8: 0.3509531 | AI8: 0.43505096 | AJ8: 0.52168274 | AK8: 0.6102333 | AL8: 0.70005804 | AM8: 0.79049486 | AN8: 0.8808584 | AO8: 0.9704542 | AP8: 1.0585775 | AQ8: 1.1445189 | AR8: 1.2275743 | AS8: 1.3070517 | AT8: 1.382268 | AU8: 1.4525737 | AV8: 1.5173446 | AW8: 1.5759974 | AX8: 1.8327705 | AY8: 1.7937174 | AZ8: 1.7614325 | BA8: 1.7361155 | BB8: 1.7179213 | BC8: 1.7069597 | BD8: 1.7032986 | BE8: 1.7069597 | BF8: 1.7179213 | BG8: 1.7361155 | BH8: 1.7614325 | BI8: 1.7937174 | BJ8: 1.8327694 | BK8: 1.8783474 | BL8: 1.9301653 | BM8: 1.9878969 | BN8: 0.051173206 | BO8: 0.11958313 | BP8: 0.1926794 | BQ8: 0.26997662 | BR8: 0.35095215 | BS8: 0.43504903 | BT8: 0.52168083 | BU8: 0.6102314 | BV8: 0.700057
A9: 0 | B9: 1.4323004 | C9: 1.3601074 | D9: 1.2887688 | E9: 1.2188206 | F9: 1.1507664 | G9: 1.085104 | H9: 1.0223007 | I9: 0.9628029 | J9: 0.90702057 | K9: 0.8553448 | L9: 0.80813026 | M9: 0.7656975 | N9: 0.7283306 | O9: 0.69628143 | P9: 0.6697655 | Q9: 0.6489582 | R9: 0.6340008 | S9: 0.62498474 | T9: 0.62197304 | U9: 0.62498474 | V9: 0.6340008 | W9: 0.6489582 | X9: 0.6697655 | Y9: 0.69628143 | Z9: 0.7283306 | AA9: 0.76569563 | AB9: 0.80813026 | AC9: 0.8553429 | AD9: 0.90701866 | AE9: 0.962801 | AF9: 1.0223007 | AG9: 1.085104 | AH9: 1.1507645 | AI9: 1.2188187 | AJ9: 1.2887669 | AK9: 1.3601055 | AL9: 1.4322987 | AM9: 1.5048103 | AN9: 1.5770855 | AO9: 1.6485692 | AP9: 1.7187023 | AQ9: 1.7869301 | AR9: 1.852707 | AS9: 1.9154987 | AT9: 1.9747887 | AU9: 0.030086517 | AV9: 0.08092594 | AW9: 0.12687588 | AX9: 0.7283306 | AY9: 0.69628143 | AZ9: 0.6697655 | BA9: 0.6489582 | BB9: 0.6339989 | BC9: 0.62498283 | BD9: 0.62197113 | BE9: 0.62498283 | BF9: 0.6339989 | BG9: 0.6489582 | BH9: 0.6697655 | BI9: 0.6962796 | BJ9: 0.7283287 | BK9: 0.7656936 | BL9: 0.80812836 | BM9: 0.8553429 | BN9: 0.90701675 | BO9: 0.9627991 | BP9: 1.0223007 | BQ9: 1.0851021 | BR9: 1.1507645 | BS9: 1.2188168 | BT9: 1.2887669 | BU9: 1.3601036 | BV9: 1.4322987
A10: 38 | B10: 1.6279964 | C10: 1.5759983 | D10: 1.5173454 | E10: 1.4525747 | F10: 1.3822699 | G10: 1.3070526 | H10: 1.2275763 | I10: 1.1445198 | J10: 1.0585775 | K10: 0.97045606 | L10: 0.8808593 | M10: 0.7904959 | N10: 0.7000599 | O10: 0.61023426 | P10: 0.5216837 | Q10: 0.43505192 | R10: 0.35095406 | S10: 0.26997852 | T10: 0.19268227 | U10: 0.11958599 | V10: 0.05117416 | W10: 1.9878988 | X10: 1.9301682 | Y10: 1.8783493 | Z10: 1.8327713 | AA10: 1.7937182 | AB10: 1.7614336 | AC10: 1.7361155 | AD10: 1.7179213 | AE10: 1.7069606 | AF10: 1.7032995 | AG10: 1.7069606 | AH10: 1.7179213 | AI10: 1.7361155 | AJ10: 1.7614325 | AK10: 1.7937174 | AL10: 1.8327705 | AM10: 1.8783493 | AN10: 1.9301661 | AO10: 1.9878979 | AP10: 0.051173206 | AQ10: 0.11958313 | AR10: 0.19268131 | AS10: 0.26997757 | AT10: 0.35095215 | AU10: 0.43505096 | AV10: 0.52168274 | AW10: 0.61023235 | AX10: 0.70005894 | AY10: 0.6102333 | AZ10: 0.52168274 | BA10: 0.43505096 | BB10: 0.3509531 | BC10: 0.26997757 | BD10: 0.19268131 | BE10: 0.11958408 | BF10: 0.051173206 | BG10: 1.9878979 | BH10: 1.9301661 | BI10: 1.8783485 | BJ10: 1.8327705 | BK10: 1.7937164 | BL10: 1.7614317 | BM10: 1.7361144 | BN10: 1.7179195 | BO10: 1.7069588 | BP10: 1.7032976 | BQ10: 1.7069578 | BR10: 1.7179195 | BS10: 1.7361144 | BT10: 1.7614307 | BU10: 1.7937156 | BV10: 1.8327684
A11: 1 | B11: 0.1675415 | C11: 0.12687588 | D11: 0.08092594 | E11: 0.030086517 | F11: 1.9747906 | G11: 1.9154987 | H11: 1.8527088 | I11: 1.7869301 | J11: 1.7187023 | K11: 1.648571 | L11: 1.5770874 | M11: 1.5048122 | N11: 1.4323004 | O11: 1.3601055 | P11: 1.2887688 | Q11: 1.2188187 | R11: 1.1507645 | S11: 1.085104 | T11: 1.0223007 | U11: 0.962801 | V11: 0.90702057 | W11: 0.8553448 | X11: 0.80813026 | Y11: 0.76569563 | Z11: 0.7283287 | AA11: 0.69628143 | AB11: 0.6697655 | AC11: 0.6489582 | AD11: 0.6339989 | AE11: 0.62498474 | AF11: 0.62197113 | AG11: 0.62498474 | AH11: 0.6339989 | AI11: 0.6489582 | AJ11: 0.6697655 | AK11: 0.69628143 | AL11: 0.7283287 | AM11: 0.76569563 | AN11: 0.80812836 | AO11: 0.8553429 | AP11: 0.90701866 | AQ11: 0.962801 | AR11: 1.0223007 | AS11: 1.085104 | AT11: 1.1507645 | AU11: 1.2188187 | AV11: 1.2887669 | AW11: 1.3601055 | AX11: 1.4322987 | AY11: 1.3601055 | AZ11: 1.2887669 | BA11: 1.2188187 | BB11: 1.1507645 | BC11: 1.085104 | BD11: 1.0223007 | BE11: 0.962801 | BF11: 0.90701866 | BG11: 0.8553429 | BH11: 0.80812836 | BI11: 0.76569563 | BJ11: 0.7283287 | BK11: 0.6962796 | BL11: 0.6697655 | BM11: 0.6489582 | BN11: 0.63399696 | BO11: 0.6249809 | BP11: 0.6219692 | BQ11: 0.6249809 | BR11: 0.63399696 | BS11: 0.6489582 | BT11: 0.6697655 | BU11: 0.6962796 | BV11: 0.7283268
A12: 37 | B12: 1.6279964 | C12: 1.6728582 | D12: 1.710163 | E12: 1.7395554 | F12: 1.7607555 | G12: 1.7735586 | H12: 1.7778397 | I12: 1.7735586 | J12: 1.7607555 | K12: 1.7395554 | L12: 1.7101641 | M12: 1.6728582 | N12: 1.6279964 | O12: 1.5759983 | P12: 1.5173454 | Q12: 1.4525747 | R12: 1.3822699 | S12: 1.3070517 | T12: 1.2275763 | U12: 1.1445198 | V12: 1.0585775 | W12: 0.97045606 | X12: 0.8808593 | Y12: 0.7904959 | Z12: 0.70005894 | AA12: 0.6102333 | AB12: 0.5216837 | AC12: 0.43505192 | AD12: 0.35095406 | AE12: 0.26997852 | AF12: 0.19268227 | AG12: 0.11958504 | AH12: 0.05117416 | AI12: 1.9878988 | AJ12: 1.9301672 | AK12: 1.8783493 | AL12: 1.8327713 | AM12: 1.7937182 | AN12: 1.7614336 | AO12: 1.7361164 | AP12: 1.7179213 | AQ12: 1.7069606 | AR12: 1.7032986 | AS12: 1.7069606 | AT12: 1.7179213 | AU12: 1.7361155 | AV12: 1.7614325 | AW12: 1.7937174 | AX12: 1.6279964 | AY12: 1.5759974 | AZ12: 1.5173454 | BA12: 1.4525747 | BB12: 1.3822689 | BC12: 1.3070517 | BD12: 1.2275753 | BE12: 1.1445198 | BF12: 1.0585775 | BG12: 0.97045517 | BH12: 0.8808584 | BI12: 0.79049486 | BJ12: 0.70005894 | BK12: 0.6102333 | BL12: 0.52168274 | BM12: 0.43505096 | BN12: 0.3509531 | BO12: 0.26997757 | BP12: 0.19268036 | BQ12: 0.11958313 | BR12: 0.051173206 | BS12: 1.9878969 | BT12: 1.9301653 | BU12: 1.8783474 | BV12: 1.8327694
